<?xml version="1.0" encoding="UTF-8"?>
<testng-results skipped="0" failed="1" ignored="0" total="3" passed="2">
  <reporter-output>
  </reporter-output>
  <suite name="Surefire suite" duration-ms="45243" started-at="2020-03-30T01:24:52 IST" finished-at="2020-03-30T01:25:37 IST">
    <groups>
    </groups>
    <test name="Surefire test" duration-ms="45243" started-at="2020-03-30T01:24:52 IST" finished-at="2020-03-30T01:25:37 IST">
      <class name="jenkins.selenium_testng_jenkins.AppTest">
        <test-method status="PASS" signature="shouldAnswerWithTrue()[pri:0, instance:jenkins.selenium_testng_jenkins.AppTest@cc285f4]" name="shouldAnswerWithTrue" duration-ms="2" started-at="2020-03-30T01:25:37 IST" finished-at="2020-03-30T01:25:37 IST">
          <reporter-output>
          </reporter-output>
        </test-method> <!-- shouldAnswerWithTrue -->
      </class> <!-- jenkins.selenium_testng_jenkins.AppTest -->
      <class name="urllogin.LoginTest">
        <test-method status="PASS" signature="beforetest()[pri:0, instance:urllogin.LoginTest@c038203]" name="beforetest" is-config="true" duration-ms="2978" started-at="2020-03-30T01:24:52 IST" finished-at="2020-03-30T01:24:55 IST">
          <reporter-output>
          </reporter-output>
        </test-method> <!-- beforetest -->
        <test-method status="PASS" signature="login()[pri:0, instance:urllogin.LoginTest@c038203]" name="login" duration-ms="30705" started-at="2020-03-30T01:24:55 IST" finished-at="2020-03-30T01:25:26 IST">
          <reporter-output>
          </reporter-output>
        </test-method> <!-- login -->
        <test-method status="FAIL" signature="loginfail()[pri:0, instance:urllogin.LoginTest@c038203]" name="loginfail" duration-ms="11268" started-at="2020-03-30T01:25:26 IST" finished-at="2020-03-30T01:25:37 IST">
          <exception class="java.lang.AssertionError">
            <message>
              <![CDATA[expected [Home | Let's Kode It] but found [Let's Kode It]]]>
            </message>
            <full-stacktrace>
              <![CDATA[java.lang.AssertionError: expected [Home | Let's Kode It] but found [Let's Kode It]
at org.testng.Assert.fail(Assert.java:97)
at org.testng.Assert.assertEqualsImpl(Assert.java:136)
at org.testng.Assert.assertEquals(Assert.java:118)
at org.testng.Assert.assertEquals(Assert.java:575)
at org.testng.Assert.assertEquals(Assert.java:585)
at urllogin.LoginTest.loginfail(LoginTest.java:41)
at sun.reflect.NativeMethodAccessorImpl.invoke0(Native Method)
at sun.reflect.NativeMethodAccessorImpl.invoke(NativeMethodAccessorImpl.java:62)
at sun.reflect.DelegatingMethodAccessorImpl.invoke(DelegatingMethodAccessorImpl.java:43)
at java.lang.reflect.Method.invoke(Method.java:498)
at org.testng.internal.MethodInvocationHelper.invokeMethod(MethodInvocationHelper.java:134)
at org.testng.internal.TestInvoker.invokeMethod(TestInvoker.java:597)
at org.testng.internal.TestInvoker.invokeTestMethod(TestInvoker.java:173)
at org.testng.internal.MethodRunner.runInSequence(MethodRunner.java:46)
at org.testng.internal.TestInvoker$MethodInvocationAgent.invoke(TestInvoker.java:816)
at org.testng.internal.TestInvoker.invokeTestMethods(TestInvoker.java:146)
at org.testng.internal.TestMethodWorker.invokeTestMethods(TestMethodWorker.java:146)
at org.testng.internal.TestMethodWorker.run(TestMethodWorker.java:128)
at java.util.ArrayList.forEach(ArrayList.java:1257)
at org.testng.TestRunner.privateRun(TestRunner.java:766)
at org.testng.TestRunner.run(TestRunner.java:587)
at org.testng.SuiteRunner.runTest(SuiteRunner.java:384)
at org.testng.SuiteRunner.runSequentially(SuiteRunner.java:378)
at org.testng.SuiteRunner.privateRun(SuiteRunner.java:337)
at org.testng.SuiteRunner.run(SuiteRunner.java:286)
at org.testng.SuiteRunnerWorker.runSuite(SuiteRunnerWorker.java:53)
at org.testng.SuiteRunnerWorker.run(SuiteRunnerWorker.java:96)
at org.testng.TestNG.runSuitesSequentially(TestNG.java:1187)
at org.testng.TestNG.runSuitesLocally(TestNG.java:1109)
at org.testng.TestNG.runSuites(TestNG.java:1039)
at org.testng.TestNG.run(TestNG.java:1007)
at org.apache.maven.surefire.testng.TestNGExecutor.run(TestNGExecutor.java:135)
at org.apache.maven.surefire.testng.TestNGDirectoryTestSuite.executeMulti(TestNGDirectoryTestSuite.java:193)
at org.apache.maven.surefire.testng.TestNGDirectoryTestSuite.execute(TestNGDirectoryTestSuite.java:94)
at org.apache.maven.surefire.testng.TestNGProvider.invoke(TestNGProvider.java:146)
at org.apache.maven.surefire.booter.ForkedBooter.invokeProviderInSameClassLoader(ForkedBooter.java:384)
at org.apache.maven.surefire.booter.ForkedBooter.runSuitesInProcess(ForkedBooter.java:345)
at org.apache.maven.surefire.booter.ForkedBooter.execute(ForkedBooter.java:126)
at org.apache.maven.surefire.booter.ForkedBooter.main(ForkedBooter.java:418)
]]>
            </full-stacktrace>
          </exception> <!-- java.lang.AssertionError -->
          <reporter-output>
          </reporter-output>
        </test-method> <!-- loginfail -->
        <test-method status="PASS" signature="aftertest()[pri:0, instance:urllogin.LoginTest@c038203]" name="aftertest" is-config="true" duration-ms="223" started-at="2020-03-30T01:25:37 IST" finished-at="2020-03-30T01:25:37 IST">
          <reporter-output>
          </reporter-output>
        </test-method> <!-- aftertest -->
      </class> <!-- urllogin.LoginTest -->
    </test> <!-- Surefire test -->
  </suite> <!-- Surefire suite -->
</testng-results>
